Workbook

Sheet Rubriques
A1: Rubriques | B1: COMPTE | C1: Chapitre | D1: Solde
A2: Charges_int_epargne | B2: 601610000 | C2: 601610000 INT SUR DEPOT A TERME INST | D2: =IF(B2="","",IFERROR(INDEX(Balance!$E$2:$E$800,MATCH(B2,Balance!$A$2:$A$800,0)),"Non trouvé")) -> -118247811
A3: Charges_int_epargne | B3: 602511000 | C3: 602511000 INTERETS SUR DEPOTS A VUE | D3: =IF(B3="","",IFERROR(INDEX(Balance!$E$2:$E$800,MATCH(B3,Balance!$A$2:$A$800,0)),"Non trouvé")) -> -2033
A4: Charges_int_epargne | B4: 602520000 | C4: 602520000 INTERETS EPARGNE PROJET | D4: =IF(B4="","",IFERROR(INDEX(Balance!$E$2:$E$800,MATCH(B4,Balance!$A$2:$A$800,0)),"Non trouvé")) -> -13362857
A5: Charges_int_epargne | B5: 602521000 | C5: 602521000 INTERETS CAT DEE 3 À 6 MOIS | D5: =IF(B5="","",IFERROR(INDEX(Balance!$E$2:$E$800,MATCH(B5,Balance!$A$2:$A$800,0)),"Non trouvé")) -> -3000483
A6: Charges_int_epargne | B6: 602522000 | C6: 602522000 INTERETS CAT DE 6 A 12 MOIS | D6: =IF(B6="","",IFERROR(INDEX(Balance!$E$2:$E$800,MATCH(B6,Balance!$A$2:$A$800,0)),"Non trouvé")) -> -11068326
A7: Charges_int_epargne | B7: 602523000 | C7: 602523000 INTETETS CAT PLUS DE 12 MOI | D7: =IF(B7="","",IFERROR(INDEX(Balance!$E$2:$E$800,MATCH(B7,Balance!$A$2:$A$800,0)),"Non trouvé")) -> -46250353
A8: Charges_int_epargne | B8: 602524000 | C8: 602524000 INTERETS DAT INSTITUTIONNE | D8: =IF(B8="","",IFERROR(INDEX(Balance!$E$2:$E$800,MATCH(B8,Balance!$A$2:$A$800,0)),"Non trouvé")) -> -176016986
A9: Charges_int_epargne | B9: 602531000 | C9: 602531000 INTERETS EPARGNE SPECIALE | D9: =IF(B9="","",IFERROR(INDEX(Balance!$E$2:$E$800,MATCH(B9,Balance!$A$2:$A$800,0)),"Non trouvé")) -> -173815496
A11: charges_financieres | B11: 601750000 | C11: 601750000 INTERETS EMPRUNTS C.T. | D11: =IF(B11="","",IFERROR(INDEX(Balance!$E$2:$E$800,MATCH(B11,Balance!$A$2:$A$800,0)),"Non trouvé")) -> 0
A12: charges_financieres | B12: 601780000 | C12: 601780000 INTERETS EMPRUNTS A TERME | D12: =IF(B12="","",IFERROR(INDEX(Balance!$E$2:$E$800,MATCH(B12,Balance!$A$2:$A$800,0)),"Non trouvé")) -> -2824459039
A13: charges_financieres | B13: 601781000 | C13: 601781000 INTERETS SUR EMPRUNTS A T | D13: =IF(B13="","",IFERROR(INDEX(Balance!$E$2:$E$800,MATCH(B13,Balance!$A$2:$A$800,0)),"Non trouvé")) -> -985339
A14: charges_financieres | B14: 601900000 | C14: 601900000 COMMISSIONS PAYEES | D14: =IF(B14="","",IFERROR(INDEX(Balance!$E$2:$E$800,MATCH(B14,Balance!$A$2:$A$800,0)),"Non trouvé")) -> -213973114
... A184: recuperation_pertes_et_creances_amorties | B184: 772300000 | C184: 772300000 PROFITS EXCEPTIONNELS | D184: =IF(B184="","",IFERROR(INDEX(Balance!$E$2:$E$800,MATCH(B184,Balance!$A$2:$A$800,0)),"Non trouvé")) -> 20816927

Sheet Balance
A1: COMPTE | B1: LIBELLE | C1: SOLDE_CUMULE_DEBIT | D1: SOLDE_CUMULE_CREDIT | E1: SOLDE
A2: 49999999 | B2: COMPTE D'EQUILIBRE IMPORT | E2: =D2-C2 -> 0
A3: 101110126 | B3: CAISSE DAKAR | D3: 1 | E3: =D3-C3 -> 1
A4: 101110201 | B4: PETITE CAISSE KAOLACK | E4: =D4-C4 -> 0
A5: 101110202 | B5: CAISSE UNITE 4 | C5: 50936815 | E5: =D5-C5 -> -50936815
A6: 101110207 | B6: CAISSE MBIRKILANE | C6: 1704275 | E6: =D6-C6 -> -1704275
A7: 101110208 | B7: CAISSE NDORONG | E7: =D7-C7 -> 0
A8: 101110209 | B8: CAISSE GUINGUINEO | C8: 1921000 | E8: =D8-C8 -> -1921000
A9: 101110215 | B9: CAISSE DIEUPPEUL | C9: 14718340 | E9: =D9-C9 -> -14718340
A10: 101110216 | B10: CAISSE PATTE D'OIE | E10: =D10-C10 -> 0
A11: 101110301 | B11: PETITE CAISSE ZIGUINCHOR | E11: =D11-C11 -> 0
A12: 101110302 | B12: CAISSE YARAKH | E12: =D12-C12 -> 0
A13: 101110401 | B13: PETITE CAISSE KOLDA | E13: =D13-C13 -> 0
A14: 101110502 | B14: PETITE CAISSE LOUGA | E14: =D14-C14 -> 0
A15: 101110601 | B15: PETITE CAISSE DIOURBEL | E15: =D15-C15 -> 0
A16: 101110701 | B16: PETITE CAISSE OURO | E16: =D16-C16 -> 0
A17: 101110801 | B17: PETITE CAISSE TAMBA | E17: =D17-C17 -> 0
A18: 101110901 | B18: PETITE CAISSE SAINT LOUIS | E18: =D18-C18 -> 0
A19: 101110902 | B19: PETITE CAISSE THIES | E19: =D19-C19 -> 0
A20: 101110903 | B20: CAISSE MEKHE | C20: 10657300 | E20: =D20-C20 -> -10657300
A21: 101110905 | B21: CAISSE SANTHIABA | E21: =D21-C21 -> 0
A22: 101111201 | B22: PETITE CAISSE MBOUR | E22: =D22-C22 -> 0
A23: 101111202 | B23: CAISSE 11 NOVEMBRE | C23: 5766165 | E23: =D23-C23 -> -5766165
A24: 101111301 | B24: PETITE CAISSE TOUBA | E24: =D24-C24 -> 0
A25: 101111302 | B25: PETITE CAISSE TOUBA | E25: =D25-C25 -> 0
A26: 101111503 | B26: PETITE CAISSE PLATEAU | E26: =D26-C26 -> 0
A27: 101111903 | B27: CAISSE THIES RTE DE MBOUR | C27: 2196205 | E27: =D27-C27 -> -2196205
A28: 101111905 | B28: CAISSE NGALLELE STLOUIS | C28: 1177090 | E28: =D28-C28 -> -1177090
A29: 101120112 | B29: CAISSE COLOBANE | C29: 19090485 | E29: =D29-C29 -> -19090485
A30: 101120116 | B30: CAISSE MEDINA | E30: =D30-C30 -> 0
A31: 101120117 | B31: CAISSE SANDAGA | C31: 12524170 | E31: =D31-C31 -> -12524170
A32: 101120118 | B32: CAISSE MEDINA RUE 9 | C32: 58357910 | E32: =D32-C32 -> -58357910
A33: 101120125 | B33: CAISSE DALIFORT | C33: 11439400 | E33: =D33-C33 -> -11439400
A34: 101120129 | B34: CAISSE YOFF | C34: 9349025 | E34: =D34-C34 -> -9349025
A35: 101120140 | B35: CAISSE HLM | C35: 8168935 | E35: =D35-C35 -> -8168935
A36: 101120150 | B36: CAISSE OUAKAM | C36: 4837325 | E36: =D36-C36 -> -4837325
A37: 101120203 | B37: CAISSE KAFFRINE | C37: 102789223 | E37: =D37-C37 -> -102789223
A38: 101120204 | B38: CAISSE FATICK | C38: 3896305 | E38: =D38-C38 -> -3896305
A39: 101120205 | B39: CAISSE PASSY | C39: 3061100 | E39: =D39-C39 -> -3061100
A40: 101120206 | B40: CAISSE KOUNGHEUL | C40: 33157365 | E40: =D40-C40 -> -33157365
...
